Workbook
Name bclcap: [1]areacap!$A$330:$B$354
Name BCLcap_el: #REF!
Name BCLel_cap: [2]CapTwTable!$B$6:$D$30
Name bclelev: [1]areacap!$B$330:$C$354
Name BCLfb_q: [2]CapTwTable!$F$6:$H$15
Name BCLstart_el: [2]Power!$AO$14
Name bluarea: #REF!
Name blucap: [1]areacap!$C$30:$F$47
Name bluelev: [1]areacap!$A$30:$F$47
Name blulbel: #REF!
Name bluname: #REF!
Name BluQ: [2]NonP!$D$16
Name bluubel: #REF!
Name Bs: [2]CapTwTable!$F$26:$H$37
Name cgrarea: #REF!
Name CGReffective: #REF!
Name cgrelev: [1]areacap!$A$182:$F$200
Name cgrelev_storage: [1]areacap!$Q$3:$R$301
Name cgrES: #REF!
Name cgrlbel: #REF!
Name CGRMW: [2]baseLoad!$D$12
Name cgrname: #REF!
Name CgrQ: #REF!
Name CGRspill: [2]baseLoad!$F$12
Name CGRtotal: [2]baseLoad!$H$12
Name CGRturbine: [2]baseLoad!$E$12
Name cgrubel: #REF!
Name cotarea: #REF!
Name cotcap: [1]areacap!$C$132:$F$149
Name cotelev: [1]areacap!$A$132:$F$149
Name cotlbel: #REF!
Name cotname: #REF!
Name CotQ: [2]NonP!$D$14
Name cotubel: #REF!
Name detarea: #REF!
Name detcap: [1]areacap!$C$211:$F$230
Name detelev: [1]areacap!$A$211:$F$230
Name detlbel: #REF!
Name detname: #REF!
Name detubel: #REF!
Name DETunit_q: [2]Power!$AJ$14
Name dexcap: [1]areacap!$A$361:$B$372
Name DEXcap_el: #REF!
Name DEXel_cap: [2]CapTwTable!$AD$6:$AF$17
Name dexelev: [1]areacap!$B$361:$C$372
Name DEXfb_q: [2]CapTwTable!$AI$6:$AK$11
Name DEXstart_el: [2]Power!$K$14
Name DEXunit_q: [2]Power!$F$14
Name dorarea: #REF!
Name dorcap: [1]areacap!$C$110:$F$122
Name dorelev: [1]areacap!$A$110:$F$122
Name dorlbel: #REF!
Name dorname: #REF!
Name DorQ: [2]NonP!$D$15
Name dorubel: #REF!
Name Ds: [2]CapTwTable!$AC$37:$AE$48
Name Dt: [2]CapTwTable!$AC$23:$AE$32
Name ELEV: #REF!
Name ELEVATION: #REF!
Name falarea: #REF!

Sheet CriticalFishFlows
A1: Critical Fish Flows
A2: When below this level, BiOp ramp rates apply. When above, high flow ramp rates apply.
A3: From WillametteReservoirStatistics20240904.xlsx
A6: OrderID | B6: Project | C6: Critical Fish Flow
A7: 1 | B7: Hills Creek | C7: 1500
A8: 2 | B8: Lookout Point | C8: 3000
A9: 3 | B9: Fall Creek | C9: 700
A10: 4 | B10: Cottage Grove | C10: 800
A11: 5 | B11: Dorena | C11: 1000
A12: 6 | B12: Fern Ridge | C12: 300
A13: 7 | B13: Cougar | C13: 1200
A14: 8 | B14: Blue River | C14: 700
A15: 9 | B15: Green Peter | C15: 2000
A16: 10 | B16: Foster | C16: 2000
A17: 11 | B17: Detroit | C17: 2000

Sheet RampRates
A1: Ramp_CFS column shows the ramp rate in cfs applicable between FlowRange_Low and FlowRange_High
A2: If Ramp_CFS not specified, Ramp_Pct (percent change in flows) must b used instead.
A3: From WillametteReservoirStatistics20240904.xlsx
A4: There are increasing (Up) and decreasing (Down) ramp rates, and two flavors: high flow and BiOp. BiOp apply below the critical fish flow.
C5: High Flow or BiOp
A6: OrderID | B6: Project | C6: Regime | D6: UpOrDown | E6: Timestep | F6: FlowRange_Low | G6: FlowRange_High | H6: Ramp_CFS | I6: Ramp_Pct | J6: Stage | K6: Note
A7: 1 | B7: Hills Creek | C7: High Flow | D7: Up | E7: Hourly | F7: 0 | G7: 1000 | H7: 300
A8: 2 | B8: Hills Creek | C8: High Flow | D8: Up | E8: Hourly | F8: 1000 | G8: 5000 | H8: 500
A9: 3 | B9: Hills Creek | C9: High Flow | D9: Up | E9: Hourly | F9: 5000 | G9: 8000 | H9: 800
A10: 4 | B10: Hills Creek | C10: High Flow | D10: Up | E10: Hourly | F10: 8000 | G10: 999999 | H10: 1500
A11: 5 | B11: Lookout Point | C11: High Flow | D11: Up | E11: Hourly | F11: 0 | G11: 1000 | H11: 500
A12: 6 | B12: Lookout Point | C12: High Flow | D12: Up | E12: Hourly | F12: 1000 | G12: 4000 | H12: 1000
A13: 7 | B13: Lookout Point | C13: High Flow | D13: Up | E13: Hourly | F13: 4000 | G13: 15000 | H13: 1500
A14: 8 | B14: Fall Creek | C14: High Flow | D14: Up | E14: Hourly | F14: 0 | G14: 1000 | H14: 300
A15: 9 | B15: Fall Creek | C15: High Flow | D15: Up | E15: Hourly | F15: 1000 | G15: 4000 | H15: 500
A16: 10 | B16: Fall Creek | C16: High Flow | D16: Up | E16: Hourly | F16: 4000 | G16: 99999 | H16: 800
A17: 11 | B17: Cottage Grove | C17: High Flow | D17: Up | E17: Hourly | F17: 0 | G17: 99999 | H17: 350
A18: 12 | B18: Dorena | C18: High Flow | D18: Up | E18: Hourly | F18: 0 | G18: 2000 | H18: 500
... A42: 36 | B42: Detroit | C42: High Flow | D42: Up | E42: Hourly | F42: 17000 | G42: 999999 | H42: 2000
A43: 37 | B43: Hills Creek | C43: High Flow | D43: Down | E43: Hourly | I43: 0.2
A44: 38 | B44: Lookout Point | C44: High Flow | D44: Down | E44: Hourly | F44: 0 | G44: 2000 | H44: 700
A45: 39 | B45: Lookout Point | C45: High Flow | D45: Down | E45: Hourly | F45: 2000 | G45: 5000 | H45: 1500
A46: 40 | B46: Lookout Point | C46: High Flow | D46: Down | E46: Hourly | F46: 5000 | G46: 10000 | H46: 2500
A47: 41 | B47: Lookout Point | C47: High Flow | D47: Down | E47: Hourly | F47: 10000 | G47: 999999 | H47: 5000
A48: 42 | B48: Fall Creek | C48: High Flow | D48: Down | E48: Hourly | I48: 0.2
A49: 43 | B49: Cottage Grove | C49: High Flow | D49: Down | E49: Hourly | I49: 0.2
A50: 44 | B50: Dorena | C50: High Flow | D50: Down | E50: Hourly | I50: 0.2
A51: 45 | B51: Fern Ridge | C51: High Flow | D51: Down | E51: Hourly | I51: 0.2
A52: 46 | B52: Cougar | C52: High Flow | D52: Down | E52: Hourly | F52: 0 | G52: 999999 | H52: 500
A53: 47 | B53: Blue River | C53: High Flow | D53: Down | E53: Hourly | I53: 0.2
A54: 48 | B54: Green Peter | C54: High Flow | D54: Down | E54: Hourly | I54: 0.2
A55: 49 | B55: Foster | C55: High Flow | D55: Down | E55: Hourly | I55: 0.2
A56: 50 | B56: Detroit | C56: High Flow | D56: Down | E56: Hourly | I56: 0.2
A57: 51 | B57: Hills Creek | C57: BiOp | D57: Up | E57: Hourly | F57: 0 | G57: 999999 | H57: 200
A58: 52 | B58: Lookout Point | C58: BiOp | D58: Up | E58: Hourly | F58: 0 | G58: =INDEX(DEXO!$C$37:$C$1279,MATCH(J58,DEXO!$A$37:$A$1279,0)) -> 994.11 | H58: =G59-F59 -> 246.54 | J58: 2.6 | K58: 0.2 ft/hr at DEXO
A59: 53 | B59: Lookout Point | C59: BiOp | D59: Up | E59: Hourly | F59: =G58 -> 994.11 | G59: =INDEX(DEXO!$C$37:$C$1279,MATCH(J59,DEXO!$A$37:$A$1279,0)) -> 1240.65 | H59: =G60-F60 -> 255.57 | J59: 2.8
A60: 54 | B60: Lookout Point | C60: BiOp | D60: Up | E60: Hourly | F60: =G59 -> 1240.65 | G60: =INDEX(DEXO!$C$37:$C$1279,MATCH(J60,DEXO!$A$37:$A$1279,0)) -> 1496.22 | H60: =G61-F61 -> 263.58 | J60: 3
A61: 55 | B61: Lookout Point | C61: BiOp | D61: Up | E61: Hourly | F61: =G60 -> 1496.22 | G61: =INDEX(DEXO!$C$37:$C$1279,MATCH(J61,DEXO!$A$37:$A$1279,0)) -> 1759.8 | H61: =G62-F62 -> 270.78 | J61: 3.2
A62: 56 | B62: Lookout Point | C62: BiOp | D62: Up | E62: Hourly | F62: =G61 -> 1759.8 | G62: =INDEX(DEXO!$C$37:$C$1279,MATCH(J62,DEXO!$A$37:$A$1279,0)) -> 2030.58 | H62: =G63-F63 -> 277.35 | J62: 3.4
A63: 57 | B63: Lookout Point | C63: BiOp | D63: Up | E63: Hourly | F63: =G62 -> 2030.58 | G63: =INDEX(DEXO!$C$37:$C$1279,MATCH(J63,DEXO!$A$37:$A$1279,0)) -> 2307.93 | H63: =G64-F64 -> 283.38 | J63: 3.6
...

Sheet DEXO
A1: # //UNITED STATES GEOLOGICAL SURVEY http://water.usgs.gov/
A2: # //NATIONAL WATER INFORMATION SYSTEM http://water.usgs.gov/data.html
A3: # //DATA ARE PROVISIONAL AND SUBJECT TO CHANGE UNTIL PUBLISHED BY USGS
A4: # //RETRIEVED: 2026-06-01 21:15:02
A5: # //WARNING
A6: # //WARNING The stage-discharge rating provided in this file should be
A7: # //WARNING considered provisional and subject to change. Stage-discharge
A8: # //WARNING ratings change over time as the channel features that control
A9: # //WARNING the relation between stage and discharge vary. Users are
A10: # //WARNING cautioned to consider carefully the applicability of this
A11: # //WARNING rating before using it for decisions that concern personal or
A12: # //WARNING public safety or operational consequences.
... A34: # //SHIFT_NEXT COMMENT=" "
A35: INDEP | B35: SHIFT | C35: DEP | D35: STOR
A36: 16N | B36: 16N | C36: 16N | D36: 1S
A37: 2.58 | B37: 0 | C37: 970 | D37: *
A38: 2.59 | B38: 0 | C38: 982.04
A39: 2.6 | B39: 0 | C39: 994.11
A40: 2.61 | B40: 0 | C40: 1006.2
A41: 2.62 | B41: 0 | C41: 1018.32
A42: 2.63 | B42: 0 | C42: 1030.46
A43: 2.64 | B43: 0 | C43: 1042.63
A44: 2.65 | B44: 0 | C44: 1054.83
A45: 2.66 | B45: 0 | C45: 1067.05
A46: 2.67 | B46: 0 | C46: 1079.29
A47: 2.68 | B47: 0 | C47: 1091.56
A48: 2.69 | B48: 0 | C48: 1103.85
A49: 2.7 | B49: 0 | C49: 1116.17
... A378: 5.99 | B378: 0 | C378: 5999.39
A379: 6 | B379: 0 | C379: 6016 | D379: *
A380: 6.01 | B380: 0 | C380: 6036.25
A381: 6.02 | B381: 0 | C381: 6056.53
A382: 6.03 | B382: 0 | C382: 6076.84
A383: 6.04 | B383: 0 | C383: 6097.18
A384: 6.05 | B384: 0 | C384: 6117.54
A385: 6.06 | B385: 0 | C385: 6137.93
A386: 6.07 | B386: 0 | C386: 6158.35
A387: 6.08 | B387: 0 | C387: 6178.8
A388: 6.09 | B388: 0 | C388: 6199.27
A389: 6.1 | B389: 0 | C389: 6219.77
...

Sheet BCLO
A1: # //UNITED STATES GEOLOGICAL SURVEY http://water.usgs.gov/
A2: # //NATIONAL WATER INFORMATION SYSTEM http://water.usgs.gov/data.html
A3: # //DATA ARE PROVISIONAL AND SUBJECT TO CHANGE UNTIL PUBLISHED BY USGS
A4: # //RETRIEVED: 2026-03-16 23:10:02
A5: # //WARNING
A6: # //WARNING The stage-discharge rating provided in this file should be
A7: # //WARNING considered provisional and subject to change. Stage-discharge
A8: # //WARNING ratings change over time as the channel features that control
A9: # //WARNING the relation between stage and discharge vary. Users are
A10: # //WARNING cautioned to consider carefully the applicability of this
A11: # //WARNING rating before using it for decisions that concern personal or
A12: # //WARNING public safety or operational consequences.
... A34: # //SHIFT_NEXT COMMENT=" "
A35: INDEP | B35: SHIFT | C35: DEP | D35: STOR
A36: 16N | B36: 16N | C36: 16N | D36: 1S
A37: 1.9 | B37: 0 | C37: 372 | D37: *
A38: 1.91 | B38: 0 | C38: 376.65
A39: 1.92 | B39: 0 | C39: 381.33
A40: 1.93 | B40: 0 | C40: 386.05
A41: 1.94 | B41: 0 | C41: 390.8
A42: 1.95 | B42: 0 | C42: 395.58
A43: 1.96 | B43: 0 | C43: 400.4
A44: 1.97 | B44: 0 | C44: 405.25
A45: 1.98 | B45: 0 | C45: 410.13
A46: 1.99 | B46: 0 | C46: 415.05
A47: 2 | B47: 0 | C47: 420 | D47: *
A48: 2.01 | B48: 0 | C48: 425.03
A49: 2.02 | B49: 0 | C49: 430.09
A50: 2.03 | B50: 0 | C50: 435.19
A51: 2.04 | B51: 0 | C51: 440.33
A52: 2.05 | B52: 0 | C52: 445.5
A53: 2.06 | B53: 0 | C53: 450.7
A54: 2.07 | B54: 0 | C54: 455.94
A55: 2.08 | B55: 0 | C55: 461.22
A56: 2.09 | B56: 0 | C56: 466.53
A57: 2.1 | B57: 0 | C57: 471.87
A58: 2.11 | B58: 0 | C58: 477.25
A59: 2.12 | B59: 0 | C59: 482.67
... A86: 2.39 | B86: 0 | C86: 642.56
A87: 2.4 | B87: 0 | C87: 649 | D87: *
...

Sheet ResRegSummary
A1: From WillametteReservoirStatistics20240904.xlsx, with a few edits to formatting
B2: General Flow Guidelines
C3: High Flow Periods | I3: All other periods | O3: Minimum Conservation Pool | P3: Maximum Conservation Pool
C4: Min | D4: Critical Fish Flow | E4: Normal Evacuation Rate | F4: Max Evacuation Rate | G4: Increase per hour | H4: Decrease per hour | I4: Minimum Flow | J4: Max when augmenting for mainstem flows | K4: Increase | L4: Decrease
D5: below these rates Biop down-ramp limits apply | K5: Increase per hour | L5: Night-time Decrease per hour | M5: Day-time Decrease per hour | N5: Daily Decrease (max decrease in a 24 hour period)
B6: Hills Creek | C6: 400 | D6: 1500 cfs | E6: 6000 | F6: 8000 cfs | G6: 100-1000cfs : 300cfs 1000-5000cfs : 500cfs 5000-8000cfs : 800cfs Maximum : 1500cfs | H6: 4000 per half hour (recommend 20%) | I6: 400 cfs | K6: 200 cfs | L6: From 400 to 1700 cfs, 100 cfs/hour. Outflow above 1700 cfs is reduced 0.1 ft/hour at HCRO | M6: 0.2 ft/hour at HCRO | N6: WCM - 1.5 ft/day Biop - lesser of 1 ft/day at HCRO or 50% flow volume | O6: 1448 | P6: 1541
B7: Dexter (Lookout Point) | C7: 1200 | D7: 3000 cfs | E7: 12000 | F7: 15000 cfs | G7: 500-1000cfs : 500cfs 1000-4000cfs : 1000cfs 4000-15000cfs:1500cfs | H7: 500-2000cfs : 700cfs 2000-5000cfs : 1500cfs 5000-10000cfs: 2500cfs 10-20 kcfs : 5000cfs | I7: 1200 cfs | K7: 0.2 ft / hour and 0.5 ft/day at DEXO | L7: 0.1 ft/hour at DEXO | M7: 0.2 ft/hour at DEXO | N7: WCM - 0.5 ft/day Biop - lesser of 1 ft/day at DEXO or 50% flow volume | O7: LOP: 825.0 DEX: 690.0 | P7: LOP: 926.0 DEX:695.0
B8: Fall Creek | C8: 50 | D8: 700 cfs | E8: 3800 | F8: 4500 cfs | G8: 50-1000cfs : 300cfs 1000-4000cfs : 500cfs Maximum : 800 cfs | H8: No Limit (recommend 20%) | I8: Feb - Mar: 50 cfs April -Aug: 80 cfs Sep 1-Oct 15: 200 cfs Oct 16-Jan 30: 50 cfs | K8: 200 cfs | L8: From 50 to 500 cfs, 50 cfs/hour. Outflow above 500 cfs is reduced 0.1 ft/hour at FALO | M8: From 50 to 300 cfs, 50 cfs/hour. Outflow above 300 cfs is reduced 0.2 ft/hour at FALO | N8: lesser of 1 ft/day at FALO or 50% flow volume | O8: 728 (690 for fish) | P8: 830
B9: Cottage Grove | C9: 50 | D9: 800 cfs | E9: 2500 | F9: 3000 cfs | G9: 350 cfs | H9: No Limit (recommend 20%) | I9: Feb-Jun: 75 cfs Jul-Oct: 50 cfs Nov-Jan: Inflow | K9: 100 cfs per hour 300 cfs max per day | L9: From 50 to 800 cfs, 50 cfs/hour. Outflow above 800 cfs is reduced 0.1 ft/hour at COTO | M9: From 50 to 300 cfs, 50 cfs/hour. Outflow above 300 cfs is reduced 0.2 ft/hour at COTO | N9: lesser of 1 ft/day at COTO or 50% flow volume | O9: 750 | P9: 790
B10: Dorena | C10: 100 | D10: 1000 cfs | E10: 4000 | F10: 5000 cfs | G10: 100-2000cfs : 500cfs 2000-5000cfs : 750cfs Max per 2hrs : 1500cfs | H10: No Limit (recommend 20%) | I10: Feb-Jun: 190 cfs Jul-Oct: 100 cfs Nov-Jan: Inflow | K10: 200 cfs per hour 500 cfs max per day | L10: From 100 to 1000 cfs, 100 cfs/hour. Outflow above 1000 cfs is reduced 0.1 ft/hour at DORO | M10: From 100 to 1000 cfs, 100 cfs/hour. Outflow above 1000 cfs is reduced 0.2 ft/hour at DORO | N10: lesser of 1 ft/day at DORO or 50% flow volume | O10: 770.5 | P10: 832
B11: Fern Ridge (see comment) | C11: 50 | D11: 300 cfs | E11: 3000 | F11: 3000 cfs | G11: Normal : 750 cfs Maximum : 1000 cfs | H11: No Limit (recommend 20%) | I11: Feb-Jun: 50cfs Jul-Nov: 30cfs (at MNRO) Dec-Jan: Inflow | K11: 200 cfs | L11: From 30 to 300 cfs, 40 cfs/hour. Outflow above 300 cfs is reduced 0.1 ft/hour at FRNO | M11: From 30 to 80 cfs, 40 cfs/hour. Outflow above 300 cfs is reduced 0.2 ft/hour at FRNO | N11: lesser of 1 ft/day at FRNO or 50% flow volume | O11: 353 | P11: 373.5
B12: Cougar | C12: 300 | D12: 1200 cfs | E12: 5000 | F12: 6500 cfs | G12: 100-500cfs : 250cfs 500-6500cfs : 500cfs Maximum : 750cfs | H12: 500 cfs | I12: July 1 - May 30: 300 cfs June 1-30: 400 cfs | J12: 580 cfs, thru September (if possible) | K12: 200 cfs | L12: From 300 to 1200 cfs, 150 cfs/hour. Outflow above 2400 cfs is reduced 0.1 ft/hour at CGRO | M12: 0.2 ft/hour at CGRO | N12: lesser of 1 ft/day at CGRO or 50% flow volume | O12: 1532 | P12: 1690
B13: Blue River | C13: 50 | D13: 700 cfs | E13: 3000 | F13: 3700 cfs | G13: 50 - 100cfs : 50 cfs 100-500cfs : 100cfs 500-1000cfs : 200cfs 1000-2000cfs : 400cfs 2000-3700cfs : 600cfs | H13: 30% (recommend 20%) | I13: 50 cfs | K13: 50 - 100cfs : 50 cfs 100-500cfs : 100 cfs 500-1000cfs : 200 cfs 1000-2000cfs : 400 cfs 2000-3700cfs : 600 cfs | L13: From 50 to 700 cfs, 100 cfs/hour. Outflow above 2300 cfs is reduced 0.1 ft/hour at BLUO | M13: From 50 to 500 cfs, 100 cfs/hour. Outflow above 500 cfs is reduced 0.2 ft/hour at BLUO | N13: lesser of 1 ft/day at BLUO or 50% flow volume | O13: 1180 | P13: 1350
B14: Foster (Green Peter) | C14: 400 | D14: 2000 cfs | E14: 15000 | F14: 18000 cfs | G14: 500-1000cfs : 500cfs 1000-3000cfs : 1000cfs 3000-18000cfs : 1500cfs Maximum : 2500cfs | H14: 30% (recommend 20%) | I14: Feb 1-Mar 15: 800 cfs Mar 16-May 15: 1500 cfs May 16-Jun 30: 1100 cfs Jul 1-Aug 31: 800 cfs Sep 1-Oct 15: 1500 cfs Oct 16-Jan 31: 1100 cfs | J14: Mar 16 - May 15 3000 cfs | K14: 300 cfs | L14: 0.1 ft/hour at SSFO | M14: 0.2 ft/hour at SSFO | N14: lesser of 1 ft/day at SSFO or 50% flow volume | O14: GPR: 922.0 FOS: 613.0 | P14: GPR: 1010.0 FOS: 637.0
B15: Big Cliff (Detroit) | C15: 1000 | D15: 2000 cfs | E15: 10000 | F15: 17000 cfs | G15: 100-1000cfs : 500cfs 1000-3000cfs : 1000cfs 3000-17000cfs:1500cfs Maximum : 2000cfs | H15: No Limit (recommend 20%) | I15: Feb 1-Mar 15: 1000 cfs Mar 16-May 31: 1500 cfs Jun 1 -Jul 15: 1200 cfs Jul 16 - Aug - 31: 1000 cfs Sep 1-Oct 15: 1500 cfs Oct 16-Jan 31: 1200 cfs | J15: Mar 16 - May 31 3000 cfs | K15: 0.3 ft / hour and 0.5 ft/day at BCLO | L15: 0.1 ft/hour at BCLO | M15: 0.2 ft/hour at BCLO | N15: WCM - 0.5 ft/day Biop - lesser of 1 ft/day at BCLO or 50% flow volume | O15: DET: 1450.0 BCL 1182.0 | P15: DET: 1563.5 BCL: 1182.0
I19: discussion with OWRD in 2015
I21: Eugene water right: Flow > 2000 cfs April 1 - November 1.
I22: If less than 2000 cfs, 12 irrigators and 2 sand and gravel companies are cut off.
I23: Oakridge is also cut off from their water supply right for drinking water.
I24: http://nwp-wmlocal2.nwp.usace.army.mil/nwdp/nwp_teacup/www/willamette/eugo.pdf
I26: Eugene seems to be mostly Jasper flow and a little of the Coast Fork Flow.
I27: There are some losses between these gages and Eugene. EUGO doesn't seem to be
I28: influenced by the McKenzie River flow. In the summer there doesn't seem to be a backwater effect.
I32: Updated May 5, 2021
I33: I talked with Mike McCord, watermaster with OWRD.
I35: There is an instream water right for 2000 cfs at EUGO, but only for live flow. The water right is for 2000 cfs June 1 - Oct 31 and 2500 cfs Nov 1 - May 31.
I37: The two sand and gravel operators and irrigators mentioned below in Mary Karen's email have water rights junior to the instream flow water right. Mike already sent them letters this year notifying them they may be regulated off due to low water levels.
... I41: Kathy Warner
D43: 780
