Workbook

Sheet Readme_AboutThisFile
A1: Sourced from Willamette Flow Frequency Study

Sheet Reaches
A1: The top 5 lines of this sheet are reserved for descriptive comments. The headers should be in line 6 and data in row 7.
A2: The reaches are shown in GIS as the shapefile "Reaches.shp"
D4: ***Might want to add HMS naming conventions to Trey's master location file
F5: Proposed
A6: OrderID | B6: ReachName_HMS | C6: Upstream_Junction | D6: Downstream_Junction | E6: RoutingID | F6: Method | G6: NumSubreaches | H6: LengthMiles | I6: Slope_ft_per_mile | J6: Notes | K6: PlotGroup | L6: MaxFlow
A7: 1 | B7: MFWillametteRV_R70 | C7: HillsCreek_Out | D7: NForkWillamette_CF | E7: =A7 -> 1 | F7: ModPuls | G7: 1 | H7: 7.4 | I7: 5.1 | K7: 1 | L7: =INDEX(Junctions!$L$7:$L$61,MATCH(Reaches!C7,Junctions!$B$7:$B$61,0)) -> 34000
A8: 2 | B8: MFWillametteRV_R60 | C8: NForkWillamette_CF | D8: OakRidge_Below_NFork | E8: =A8 -> 2 | F8: ModPuls | G8: 1 | H8: 4.1 | I8: 102.7 | K8: 1 | L8: =INDEX(Junctions!$L$7:$L$61,MATCH(Reaches!C8,Junctions!$B$7:$B$61,0)) -> 81800
A9: 3 | B9: MFWillametteRV_R55 | C9: OakRidge_Below_NFork | D9: LookoutPoint_In | E9: =A9 -> 3 | F9: ModPuls | G9: 2 | H9: 17 | I9: 67.9 | J9: New Reach in HMS | K9: 1 | L9: =INDEX(Junctions!$L$7:$L$61,MATCH(Reaches!C9,Junctions!$B$7:$B$61,0)) -> 81800
A10: 3.1 | B10: MFWillametteRV_R53 | C10: LookoutPoint_In | D10: Dexter_In | E10: 9903 | F10: Null | G10: 1 | H10: 99 | I10: 99 | J10: Only for connectivity, not a real reach | K10: 1 | L10: =INDEX(Junctions!$L$7:$L$61,MATCH(Reaches!C10,Junctions!$B$7:$B$61,0)) -> 81800
A11: 3.2 | B11: MFWillametteRV_R52 | C11: Dexter_In | D11: Dexter_Out | E11: 9904 | F11: Null | G11: 1 | H11: 99 | I11: 99 | J11: Only for connectivity, not a real reach | K11: 1 | L11: =INDEX(Junctions!$L$7:$L$61,MATCH(Reaches!C11,Junctions!$B$7:$B$61,0)) -> 81800
A12: 4 | B12: MFWillametteRv_R30 | C12: Dexter_Out | D12: FallCk_CF | E12: =A12 -> 4 | F12: ModPuls | G12: 1 | H12: 5.4 | I12: 15.2 | K12: 1 | L12: =INDEX(Junctions!$L$7:$L$61,MATCH(Reaches!C12,Junctions!$B$7:$B$61,0)) -> 81800
A13: 5 | B13: FallCk_R10 | C13: FallCreek_Out | D13: FallCk_CF | E13: =A13 -> 5 | F13: ModPuls | G13: 1 | H13: 7 | I13: 19.9 | K13: 1 | L13: =INDEX(Junctions!$L$7:$L$61,MATCH(Reaches!C13,Junctions!$B$7:$B$61,0)) -> 24700
A14: 6 | B14: MFWillametteRv_R20 | C14: FallCk_CF | D14: Jasper | E14: =A14 -> 6 | F14: ModPuls | G14: 1 | H14: 3 | I14: 10.5 | K14: 1 | L14: =INDEX(Junctions!$L$7:$L$61,MATCH(Reaches!C14,Junctions!$B$7:$B$61,0)) -> 73400
A15: 7 | B15: MFWillametteRv_R10 | C15: Jasper | D15: CoastFork_CF | E15: =A15 -> 7 | F15: ModPuls | G15: 2 | H15: 8 | I15: 15 | K15: 1 | L15: =INDEX(Junctions!$L$7:$L$61,MATCH(Reaches!C15,Junctions!$B$7:$B$61,0)) -> 73400
A16: 8 | B16: RowRv_R10 | C16: Dorena_Out | D16: RowRv_CF | E16: =A16 -> 8 | F16: ModPuls | G16: 2 | H16: 7.5 | I16: 17.8 | K16: 2 | L16: =INDEX(Junctions!$L$7:$L$61,MATCH(Reaches!C16,Junctions!$B$7:$B$61,0)) -> 21400
A17: 9 | B17: CFWillametteRv_R30 | C17: CottageGrove_Out | D17: RowRv_CF | E17: =A17 -> 9 | F17: ModPuls | G17: 2 | H17: 8.8 | I17: 8.7 | K17: 2 | L17: =INDEX(Junctions!$L$7:$L$61,MATCH(Reaches!C17,Junctions!$B$7:$B$61,0)) -> 12000
A18: 10 | B18: CFWillametteRv_R20 | C18: RowRv_CF | D18: Goshen | E18: =A18 -> 10 | F18: ModPuls | G18: 5 | H18: 14.3 | I18: 14.2 | K18: 2 | L18: =INDEX(Junctions!$L$7:$L$61,MATCH(Reaches!C18,Junctions!$B$7:$B$61,0)) -> 33400
A19: 11 | B19: CFWillametteRv_R10 | C19: Goshen | D19: CoastFork_CF | E19: =A19 -> 11 | F19: ModPuls | G19: 2 | H19: 5.6 | I19: 8.8 | K19: 2 | L19: =INDEX(Junctions!$L$7:$L$61,MATCH(Reaches!C19,Junctions!$B$7:$B$61,0)) -> 33400
A20: 12 | B20: WillametteRV_R170 | C20: CoastFork_CF | D20: McKenzie_CF | E20: =A20 -> 12 | F20: ModPuls | G20: 3 | H20: 11.7 | I20: 6.5 | K20: 5 | L20: =INDEX(Junctions!$L$7:$L$61,MATCH(Reaches!C20,Junctions!$B$7:$B$61,0)) -> 140000
A21: 13 | B21: McKenzieRv_R50 | C21: TrailBridge_Out | D21: SFMckenzie_CF | E21: =A21 -> 13 | F21: Muskingum | G21: 1 | H21: 21.5 | I21: 42 | K21: 3 | L21: =INDEX(Junctions!$L$7:$L$61,MATCH(Reaches!C21,Junctions!$B$7:$B$61,0)) -> 11200
A22: 14 | B22: SFMcKenzieRv_R10 | C22: Cougar_Out | D22: SFMckenzie_CF | E22: =A22 -> 14 | F22: ModPuls | G22: 1 | H22: 4.5 | I22: 59.2 | K22: 3 | L22: =INDEX(Junctions!$L$7:$L$61,MATCH(Reaches!C22,Junctions!$B$7:$B$61,0)) -> 24500
A23: 15 | B23: McKenzieRv_R40 | C23: SFMckenzie_CF | D23: BlueRv_CF | E23: =A23 -> 15 | F23: ModPuls | G23: 1 | H23: 2.7 | I23: 23.1 | K23: 3 | L23: =INDEX(Junctions!$L$7:$L$61,MATCH(Reaches!C23,Junctions!$B$7:$B$61,0)) -> 35700
A24: 16 | B24: BlueRv_R10 | C24: BlueRiver_Out | D24: BlueRv_CF | E24: =A24 -> 16 | F24: ModPuls | G24: 1 | H24: 1.8 | I24: 167.9 | J24: New Reach in HMS | K24: 3 | L24: =INDEX(Junctions!$L$7:$L$61,MATCH(Reaches!C24,Junctions!$B$7:$B$61,0)) -> 20000
A25: 17 | B25: McKenzieRv_R30 | C25: BlueRv_CF | D25: Vida | E25: =A25 -> 17 | F25: ModPuls | G25: =ROUND(H25*5280/(60*60*5),0)-1 -> 2 | H25: 9.1 | I25: 19 | K25: 3 | L25: =INDEX(Junctions!$L$7:$L$61,MATCH(Reaches!C25,Junctions!$B$7:$B$61,0)) -> 55700
A26: 18 | B26: McKenzieRv_R25 | C26: Vida | D26: Walterville | E26: =A26 -> 18 | F26: ModPuls | G26: =ROUND(H26*5280/(60*60*5),0)-1 -> 5 | H26: 19.6 | I26: 15.5 | J26: Split this reach from original 2019 CWMS model | K26: 3 | L26: =INDEX(Junctions!$L$7:$L$61,MATCH(Reaches!C26,Junctions!$B$7:$B$61,0)) -> 64400
A27: 19 | B27: McKenzieRv_R20 | C27: Walterville | D27: Coburg | E27: =A27 -> 19 | F27: ModPuls | G27: =ROUND(H27*5280/(60*60*5),0)+2 -> 8 | H27: 20.5 | I27: 9.5 | J27: 2019 CWMS model went from Vida to Coburg | K27: 3 | L27: =INDEX(Junctions!$L$7:$L$61,MATCH(Reaches!C27,Junctions!$B$7:$B$61,0)) -> 76300
A28: 20 | B28: McKenzieRv_R10 | C28: Coburg | D28: McKenzie_CF | E28: =A28 -> 20 | F28: ModPuls | G28: 1 | H28: 3.3 | I28: 9.1 | K28: 3 | L28: =INDEX(Junctions!$L$7:$L$61,MATCH(Reaches!C28,Junctions!$B$7:$B$61,0)) -> 88200
A29: 21 | B29: WillametteRv_R160 | C29: McKenzie_CF | D29: Harrisburg | E29: =A29 -> 21 | F29: ModPuls | G29: 8 | H29: 13.2 | I29: 5.4 | K29: 5 | L29: =INDEX(Junctions!$L$7:$L$61,MATCH(Reaches!C29,Junctions!$B$7:$B$61,0)) -> 210000
A30: 22 | B30: WillametteRv_R150 | C30: Harrisburg | D30: LongTom_CF | E30: =A30 -> 22 | F30: ModPuls | G30: =ROUND(H30*5280/(60*60*5),0)-1 -> 3 | H30: 12.4 | I30: 4.1 | K30: 5 | L30: =INDEX(Junctions!$L$7:$L$61,MATCH(Reaches!C30,Junctions!$B$7:$B$61,0)) -> 210000
A31: 23 | B31: LongTomRv_R20 | C31: FernRidge_Out | D31: Monroe | E31: =A31 -> 23 | F31: ModPuls | G31: =ROUND(H31*5280/(60*60*5),0)-1 -> 4 | H31: 16.6 | I31: 4.2 | K31: 4 | L31: =INDEX(Junctions!$L$7:$L$61,MATCH(Reaches!C31,Junctions!$B$7:$B$61,0)) -> 11500
A32: 24 | B32: LongTomRv_R10 | C32: Monroe | D32: LongTom_CF | E32: =A32 -> 24 | F32: ModPuls | G32: =ROUND(H32*5280/(60*60*5),0) -> 2 | H32: 7.6 | I32: 4.4 | K32: 4 | L32: =INDEX(Junctions!$L$7:$L$61,MATCH(Reaches!C32,Junctions!$B$7:$B$61,0)) -> 19300
A33: 25 | B33: WillametteRv_R140 | C33: LongTom_CF | D33: Corvallis | E33: =A33 -> 25 | F33: ModPuls | G33: =ROUND(H33*5280/(60*60*5),0)-1 -> 4 | H33: 16.3 | I33: 4.7 | K33: 5 | L33: =INDEX(Junctions!$L$7:$L$61,MATCH(Reaches!C33,Junctions!$B$7:$B$61,0)) -> 218000
A34: 26 | B34: MarysRv_R10 | C34: Philomath | D34: Corvallis | E34: =A34 -> 26 | F34: Muskingum | G34: 1 | H34: 8.9 | I34: 5.1 | K34: 5
A35: 27 | B35: WillametteRv_R120 | C35: Corvallis | D35: Albany | E35: =A35 -> 27 | F35: ModPuls | G35: =ROUND(H35*5280/(60*60*5),0)-1 -> 3 | H35: 12.7 | I35: 2.2 | K35: 5 | L35: =INDEX(Junctions!$L$7:$L$61,MATCH(Reaches!C35,Junctions!$B$7:$B$61,0)) -> 218000
A36: 28 | B36: WillametteRv_R110 | C36: Albany | D36: Santiam_CF | E36: =A36 -> 28 | F36: ModPuls | G36: 1 | H36: 11.7 | I36: 15.4 | K36: 5 | L36: =INDEX(Junctions!$L$7:$L$61,MATCH(Reaches!C36,Junctions!$B$7:$B$61,0)) -> 218000
A37: 29 | B37: SSantiamRv_R20 | C37: GreenPeter_Out | D37: Foster_In | E37: =A37 -> 29 | F37: ModPuls | G37: =ROUND(H37*5280/(60*60*5),0)-1 -> 1 | H37: 5.6 | I37: 44.8 | J37: 2019 CWMS HMS model did not include reach from Green Peter to Foster | K37: 6 | L37: =INDEX(Junctions!$L$7:$L$61,MATCH(Reaches!C37,Junctions!$B$7:$B$61,0)) -> 25000
A38: 29.1 | B38: SSantiamRv_R17 | C38: Foster_In | D38: Foster_Out | E38: 9929 | F38: Null | G38: 1 | H38: 99 | I38: 99 | J38: Only for connectivity, not a real reach | K38: 1
A39: 30 | B39: SSantiamRv_R15 | C39: Foster_Out | D39: Waterloo | E39: =A39 -> 30 | F39: ModPuls | G39: =ROUND(H39*5280/(60*60*5),0)-1 -> 3 | H39: 14.4 | I39: 16.4 | J39: Split this reach from original 2019 CWMS model | K39: 6 | L39: =INDEX(Junctions!$L$7:$L$61,MATCH(Reaches!C39,Junctions!$B$7:$B$61,0)) -> 81000
A40: 31 | B40: SSantiamRv_R10 | C40: Waterloo | D40: NSantiam_CF | E40: =A40 -> 31 | F40: ModPuls | G40: =ROUND(H40*5280/(60*60*5),0)-1 -> 5 | H40: 21.9 | I40: 38.8 | J40: 2019 CWMS model went from Foster to Jefferson | K40: 6 | L40: =INDEX(Junctions!$L$7:$L$61,MATCH(Reaches!C40,Junctions!$B$7:$B$61,0)) -> 95200
A41: 31.1 | B41: NSantiamRv_R18 | C41: Detroit_Out | D41: BigCliff_In | E41: 9931 | F41: Null | G41: 1 | H41: 99 | I41: 99 | J41: Only for connectivity, not a real reach | K41: 6 | L41: =L43 -> 41200
...

Sheet Junctions
A1: The top 5 lines of this sheet are reserved for descriptive comments. The headers should be in line 6 and data in row 7.
A2: The junctions are shown in GIS as the shapefile "Junctions.shp"
E4: Is this a location where we want to compare the modeled routing vs observed flow? | F4: Is observed flow required at this location to make a valid routing comparison at the next downstream point? | H4: Pre-computed output from another model for comparison | I4: Pre-computed output from another model for comparison | J4: Pre-computed output from another model for comparison
F5: Typically Yes for mainstem sites and dam outlets, and No for tribs like the Luckiamute that may or may not have gage readings for a given event | G5: See the DSSFiles input for the DSS file | H5: See the DSSFiles input for the DSS file | I5: See the DSSFiles input for the DSS file | J5: See the DSSFiles input for the DSS file
A6: OrderID | B6: JunctionName_HMS | C6: JunctionName_Report | D6: ElevFt | E6: Is_Comparison_Point | F6: Is_Required | G6: Observed_Path_DSS | H6: Compare_1_Path_DSS | I6: Compare_2_Path_DSS | J6: Compare_3_Path_DSS | K6: Notes | L6: MaxFlow
A7: 1 | B7: HillsCreek_Out | C7: Hills Creek_Out | D7: 1532.5768 | E7: No | F7: Yes | G7: //HILLS CREEK/FLOW-OUT//1HOUR/BEST/ | L7: 34000
A8: 2 | B8: NForkWillamette_CF | D8: 1032.5414 | E8: No | F8: No | L8: 81800
A9: 3 | B9: OakRidge_Below_NFork | C9: MF Willamette Below North Fork | D9: 958.37115 | E9: Yes | F9: No | G9: //Oakridge below North Fork/FLOW//1HOUR/BEST/ | H9: //MF WILLAMETTE_BLW NFORK NR OAKRIDGE/FLOW//1HOUR/FIS_SSARR_ROUTED/ | I9: //OAKRIDGE_BELOW_NFORK/FLOW//1HOUR/CWMS_HMS_ROUTED/ | J9: //OAKRIDGE_BELOW_NFORK/FLOW//1HOUR// | L9: 81800
A10: 4 | B10: LookoutPoint_In | C10: Lookout Point_In | D10: 890.44666 | E10: No | F10: No | J10: //LOOKOUTPOINT_IN/FLOW//1HOUR// | L10: 81800
A11: 4.1 | B11: Dexter_In | C11: Dexter_In | D11: 670.92578 | E11: No | F11: No | L11: 81800
A12: 5 | B12: Dexter_Out | C12: Dexter_Out | D12: 670.92578 | E12: No | F12: Yes | G12: //Dexter/FLOW-OUT//1HOUR/BEST/ | L12: 81800
A13: 6 | B13: FallCreek_Out | C13: Fall Creek_Out | D13: 819.92633 | E13: No | F13: Yes | G13: //Fall Creek/FLOW-OUT//1HOUR/BEST/ | L13: 24700
A14: 7 | B14: FallCk_CF | D14: 560.97253 | E14: No | F14: No | L14: 73400
A15: 8 | B15: Jasper | C15: Jasper | D15: 521.28064 | E15: Yes | F15: Yes | G15: //Jasper/FLOW//1HOUR/BEST/ | H15: //MF WILLAMETTE+FALL TO US_JASPER/FLOW//1HOUR/FIS_SSARR_ROUTED/ | I15: //JASPER/FLOW//1HOUR/CWMS_HMS_ROUTED/ | J15: //JASPER/FLOW//1HOUR// | L15: 73400
A16: 9 | B16: Dorena_Out | C16: Dorena_Out | D16: 810.41321 | E16: No | F16: Yes | G16: //DORENA/FLOW-OUT//1HOUR/BEST/ | L16: 21400
A17: 10 | B17: CottageGrove_Out | C17: Cottage Grove_Out | D17: 797.52966 | E17: No | F17: Yes | G17: //COTTAGE GROVE/FLOW-OUT//1HOUR/BEST/ | L17: 12000
A18: 11 | B18: RowRv_CF | D18: 614.83783 | E18: No | F18: No | G18: //Saginaw/FLOW//1HOUR/BEST/ | H18: //CF WILLAMETTE+ROW/FLOW//1HOUR/FIS_SSARR_ROUTED/ | I18: //SAGINAW/FLOW//1HOUR/CWMS_HMS_ROUTED/ | J18: //ROWRV_CF/FLOW//1HOUR// | K18: Saginaw | L18: 33400
A19: 12 | B19: Goshen | C19: Goshen | D19: 480.4913 | E19: Yes | F19: Yes | G19: //Goshen/FLOW//1HOUR/BEST/ | H19: //CF WILLAMETTE+ROW TO US_GOSHEN/FLOW//1HOUR/FIS_SSARR_ROUTED/ | I19: //GOSHEN/FLOW//1HOUR/CWMS_HMS_ROUTED/ | J19: //GOSHEN/FLOW//1HOUR// | L19: 33400
A20: 13 | B20: CoastFork_CF | D20: 440.13223 | E20: No | F20: No | L20: 140000
A21: 14 | B21: TrailBridge_Out | C21: Trail Bridge_Out | D21: 1994.9756 | E21: No | F21: Yes | G21: //Trail Bridge/FLOW//1HOUR/BEST/ | L21: 11200
A22: 15 | B22: Cougar_Out | C22: Cougar_Out | D22: 1688.4771 | E22: No | F22: Yes | G22: //COUGAR/FLOW-OUT//1HOUR/BEST/ | L22: 24500
A23: 16 | B23: SFMckenzie_CF | D23: 1092.105 | E23: No | F23: No | L23: 35700
A24: 17 | B24: BlueRiver_Out | C24: Blue River_Out | D24: 1325.53 | E24: No | F24: Yes | G24: //BLUE RIVER/FLOW-OUT//1HOUR/BEST/ | L24: 20000
A25: 18 | B25: BlueRv_CF | D25: 1030.0884 | E25: No | F25: No | L25: 55700
A26: 19 | B26: Vida | C26: Vida | D26: 901.06152 | E26: Yes | F26: Yes | G26: //Vida/FLOW//1HOUR/BEST/ | H26: //MCKENZIE+BLUE TO US_VIDA/FLOW//1HOUR/FIS_SSARR_ROUTED/ | I26: //VIDA/FLOW//1HOUR/CWMS_HMS_ROUTED/ | J26: //VIDA/FLOW//1HOUR// | L26: 64400
A27: 20 | B27: Walterville | C27: Walterville | D27: 597.54858 | E27: No | F27: No | K27: Canal issues | L27: 76300
A28: 21 | B28: Coburg | C28: Coburg | D28: 399.25815 | E28: Yes | F28: No | G28: //Coburg/FLOW//1HOUR/BEST/ | H28: //ABOVE HAYDEN BRIGE AT SPRINGFIELD TO US_COBURG/FLOW//1HOUR/FIS_SSARR_ROUTED/ | I28: //COBURG/FLOW//1HOUR/CWMS_HMS_ROUTED/ | J28: //COBURG/FLOW//1HOUR// | L28: 88200
A29: 22 | B29: McKenzie_CF | D29: 369.28656 | E29: No | F29: No | L29: 210000
A30: 23 | B30: Harrisburg | C30: Harrisburg | D30: 312.26538 | E30: Yes | F30: Yes | G30: //Harrisburg/FLOW//1HOUR/BEST/ | H30: //WILLAMETTE+MCKENZIE TO US_HARRISBURG/FLOW//1HOUR/FIS_SSARR_ROUTED/ | I30: //HARRISBURG/FLOW//1HOUR/CWMS_HMS_ROUTED/ | J30: //HARRISBURG/FLOW//1HOUR// | L30: 210000
A31: 24 | B31: FernRidge_Out | C31: Fern Ridge_Out | D31: 350.02637 | E31: No | F31: Yes | G31: //FERN RIDGE/FLOW-OUT//1HOUR/BEST/ | L31: 11500
A32: 25 | B32: Monroe | C32: Monroe | D32: 284.66031 | E32: Yes | F32: No | G32: //Monroe/FLOW//1HOUR/BEST/ | H32: //LONG TOM_NR ALVADORE TO US_MONROE/FLOW//1HOUR/FIS_SSARR_ROUTED/ | I32: //MONROE/FLOW//1HOUR/CWMS_HMS_ROUTED/ | J32: //MONROE/FLOW//1HOUR// | L32: 19300
A33: 26 | B33: LongTom_CF | D33: 250.01044 | E33: No | F33: No | L33: 218000
A34: 27 | B34: Philomath | C34: Philomath | D34: 241.81633 | E34: No | F34: No | G34: //Philomath/FLOW//1HOUR/BEST/
A35: 28 | B35: Corvallis | C35: Corvallis | D35: 196.44838 | E35: Yes | F35: No | G35: //Corvallis/FLOW//1HOUR/BEST/ | I35: //CORVALLIS/FLOW//1HOUR/CWMS_HMS_ROUTED/ | J35: //CORVALLIS/FLOW//1HOUR// | L35: 218000
A36: 29 | B36: Albany | C36: Albany | D36: 173.72791 | E36: Yes | F36: Yes | G36: //Albany/FLOW//1HOUR/BEST/ | H36: //WILLAMETTE+CALAPOOIA TO US_ALBANY/FLOW//1HOUR/FIS_SSARR_ROUTED/ | I36: //ALBANY/FLOW//1HOUR/CWMS_HMS_ROUTED/ | J36: //ALBANY/FLOW//1HOUR// | L36: 218000
A37: 30 | B37: GreenPeter_Out | C37: Green Peter_Out | D37: 868.85797 | E37: No | F37: Yes | G37: //GREEN PETER/FLOW-OUT//1HOUR/BEST/ | L37: 25000
A38: 31 | B38: Foster_In | C38: Foster_In | D38: 620 | E38: No | F38: No | H38: //GREEN PETER_OUT TO FOSTER_IN/FLOW//1HOUR/FIS_SSARR_ROUTED/ | I38: //FOSTER_IN/FLOW//1HOUR/CWMS_HMS_ROUTED/ | J38: //FOSTER_IN/FLOW//1HOUR// | L38: 81000
A39: 32 | B39: Foster_Out | C39: Foster_Out | D39: 631.74554 | E39: No | F39: Yes | G39: //FOSTER/FLOW-OUT//1HOUR/BEST/ | L39: 81000
A40: 33 | B40: Waterloo | C40: Waterloo | D40: 395.65561 | E40: Yes | F40: Yes | G40: //Waterloo/FLOW//1HOUR/BEST/ | H40: //SO SANTIAM_NR FOSTER TO US_WATERLOO/FLOW//1HOUR/FIS_SSARR_ROUTED/ | J40: //WATERLOO/FLOW//1HOUR// | L40: 95200
A41: 33.1 | B41: Detroit_Out | C41: Detroit_Out | D41: 1187.8539 | E41: No | F41: No | L41: 41200
...

Sheet Muskingum
A1: The top 5 lines of this sheet are reserved for descriptive comments. The headers should be in line 6 and data in row 7.
A2: This sheet contains the candidate Muskingum routing relationships to be used for reaches.
A3: The RoutingID is linked to the Reaches tab
A6: RoutingID | B6: ReachName_HMS | C6: Initial Type | D6: Initial Discharge | E6: K | F6: X | G6: Subreaches | H6: Notes
A7: =IFERROR(INDEX(Reaches!$A$7:$A$60,MATCH(B7,Reaches!$B$7:$B$60,0)),-1) -> 13 | B7: McKenzieRv_R50 | C7: Discharge = Inflow | E7: =ROUND((114420/5280)/SQRT(0.007866*5280),1) -> 3.4 | F7: 0.25 | G7: =INDEX(Reaches!$G$7:$G$60,MATCH(B7,Reaches!$B$7:$B$60,0)) -> 1 | H7: Developed using length and slope from 2020 Post-fire HMS model
A8: =IFERROR(INDEX(Reaches!$A$7:$A$60,MATCH(B8,Reaches!$B$7:$B$60,0)),-1) -> 26 | B8: MarysRv_R10 | C8: Discharge = Inflow | E8: =ROUND(Reaches!H34/SQRT(Reaches!I34),1) -> 3.9 | F8: 0.25 | G8: =INDEX(Reaches!$G$7:$G$60,MATCH(B8,Reaches!$B$7:$B$60,0)) -> 1 | H8: Matches 2019 CWMS HMS model (original was 3.9)
A9: =IFERROR(INDEX(Reaches!$A$7:$A$60,MATCH(B9,Reaches!$B$7:$B$60,0)),-1) -> 37 | B9: LuckiamuteRv_R10 | C9: Discharge = Inflow | E9: =ROUND(Reaches!H48/SQRT(Reaches!I48),1) -> 10.1 | F9: 0.25 | G9: =INDEX(Reaches!$G$7:$G$60,MATCH(B9,Reaches!$B$7:$B$60,0)) -> 2 | H9: Modified From 2019 CWMS HMS model, originally 6.9
A10: =IFERROR(INDEX(Reaches!$A$7:$A$60,MATCH(B10,Reaches!$B$7:$B$60,0)),-1) -> 40 | B10: YamhillRv_R10 | C10: Discharge = Inflow | E10: =ROUND(Reaches!H51/SQRT(Reaches!I51),1) -> 13.6 | F10: 0.25 | G10: =INDEX(Reaches!$G$7:$G$60,MATCH(B10,Reaches!$B$7:$B$60,0)) -> 2 | H10: Modified From 2019 CWMS HMS model, originally 5.9
A11: =IFERROR(INDEX(Reaches!$A$7:$A$60,MATCH(B11,Reaches!$B$7:$B$60,0)),-1) -> 42 | B11: PuddingRv_R10 | C11: Discharge = Inflow | E11: =ROUND((Reaches!H55)/SQRT(Reaches!I55),1) -> 4 | F11: 0.25 | G11: =INDEX(Reaches!$G$7:$G$60,MATCH(B11,Reaches!$B$7:$B$60,0)) -> 1 | H11: Developed using length and slope from GIS
A12: =IFERROR(INDEX(Reaches!$A$7:$A$60,MATCH(B12,Reaches!$B$7:$B$60,0)),-1) -> 43 | B12: MolallaRv_R10 | C12: Discharge = Inflow | E12: =ROUND((Reaches!H56)/SQRT(Reaches!I56),1) -> 1.8 | F12: 0.25 | G12: =INDEX(Reaches!$G$7:$G$60,MATCH(B12,Reaches!$B$7:$B$60,0)) -> 1 | H12: Developed using length and slope from GIS
A13: =IFERROR(INDEX(Reaches!$A$7:$A$60,MATCH(B13,Reaches!$B$7:$B$60,0)),-1) -> 45 | B13: TualatinRv_R20 | C13: Discharge = Inflow | E13: 7.8 | F13: 0.25 | G13: =INDEX(Reaches!$G$7:$G$60,MATCH(B13,Reaches!$B$7:$B$60,0)) -> 3 | H13: From 2019 CWMS HMS model
A14: =IFERROR(INDEX(Reaches!$A$7:$A$60,MATCH(B14,Reaches!$B$7:$B$60,0)),-1) -> 46 | B14: TualatinRv_R10 | C14: Discharge = Inflow | E14: 35.9 | F14: 0.25 | G14: =INDEX(Reaches!$G$7:$G$60,MATCH(B14,Reaches!$B$7:$B$60,0)) -> 12 | H14: From 2019 CWMS HMS model

Sheet ModPuls
A1: The top 5 lines of this sheet are reserved for descriptive comments. The headers should be in line 6 and data in row 7.
A2: This sheet contains the candidate Modified Puls relationships to be used for each reach.
A3: The RoutingID is linked to the Reaches tab
A6: RoutingID | B6: ReachName_HMS | C6: Subreaches | D6: Storage | E6: Discharge | F6: Notes
A7: =IF(ISBLANK(B7),A6,IFERROR(INDEX(Reaches!$A$7:$A$60,MATCH(B7,Reaches!$B$7:$B$60,0)),-1)) -> 1 | B7: MFWillametteRV_R70 | C7: =IFERROR(INDEX(Reaches!$G$7:$G$60,MATCH(B7,Reaches!$B$7:$B$60,0)),"") -> 1 | D7: 0 | E7: 0
A8: =IF(ISBLANK(B8),A7,IFERROR(INDEX(Reaches!$A$7:$A$60,MATCH(B8,Reaches!$B$7:$B$60,0)),-1)) -> 1 | C8: =IFERROR(INDEX(Reaches!$G$7:$G$60,MATCH(B8,Reaches!$B$7:$B$60,0)),"") | D8: 823 | E8: 450
A9: =IF(ISBLANK(B9),A8,IFERROR(INDEX(Reaches!$A$7:$A$60,MATCH(B9,Reaches!$B$7:$B$60,0)),-1)) -> 1 | C9: =IFERROR(INDEX(Reaches!$G$7:$G$60,MATCH(B9,Reaches!$B$7:$B$60,0)),"") | D9: 849 | E9: 500
A10: =IF(ISBLANK(B10),A9,IFERROR(INDEX(Reaches!$A$7:$A$60,MATCH(B10,Reaches!$B$7:$B$60,0)),-1)) -> 1 | C10: =IFERROR(INDEX(Reaches!$G$7:$G$60,MATCH(B10,Reaches!$B$7:$B$60,0)),"") | D10: 1040 | E10: 1000
A11: =IF(ISBLANK(B11),A10,IFERROR(INDEX(Reaches!$A$7:$A$60,MATCH(B11,Reaches!$B$7:$B$60,0)),-1)) -> 1 | C11: =IFERROR(INDEX(Reaches!$G$7:$G$60,MATCH(B11,Reaches!$B$7:$B$60,0)),"") | D11: 1206 | E11: 1500
A12: =IF(ISBLANK(B12),A11,IFERROR(INDEX(Reaches!$A$7:$A$60,MATCH(B12,Reaches!$B$7:$B$60,0)),-1)) -> 1 | C12: =IFERROR(INDEX(Reaches!$G$7:$G$60,MATCH(B12,Reaches!$B$7:$B$60,0)),"") | D12: 1364 | E12: 2000
A13: =IF(ISBLANK(B13),A12,IFERROR(INDEX(Reaches!$A$7:$A$60,MATCH(B13,Reaches!$B$7:$B$60,0)),-1)) -> 1 | C13: =IFERROR(INDEX(Reaches!$G$7:$G$60,MATCH(B13,Reaches!$B$7:$B$60,0)),"") | D13: 1679 | E13: 3000
A14: =IF(ISBLANK(B14),A13,IFERROR(INDEX(Reaches!$A$7:$A$60,MATCH(B14,Reaches!$B$7:$B$60,0)),-1)) -> 1 | C14: =IFERROR(INDEX(Reaches!$G$7:$G$60,MATCH(B14,Reaches!$B$7:$B$60,0)),"") | D14: 1980 | E14: 4000
A15: =IF(ISBLANK(B15),A14,IFERROR(INDEX(Reaches!$A$7:$A$60,MATCH(B15,Reaches!$B$7:$B$60,0)),-1)) -> 1 | C15: =IFERROR(INDEX(Reaches!$G$7:$G$60,MATCH(B15,Reaches!$B$7:$B$60,0)),"") | D15: 2277 | E15: 5000
A16: =IF(ISBLANK(B16),A15,IFERROR(INDEX(Reaches!$A$7:$A$60,MATCH(B16,Reaches!$B$7:$B$60,0)),-1)) -> 1 | C16: =IFERROR(INDEX(Reaches!$G$7:$G$60,MATCH(B16,Reaches!$B$7:$B$60,0)),"") | D16: 2530 | E16: 6000
A17: =IF(ISBLANK(B17),A16,IFERROR(INDEX(Reaches!$A$7:$A$60,MATCH(B17,Reaches!$B$7:$B$60,0)),-1)) -> 1 | C17: =IFERROR(INDEX(Reaches!$G$7:$G$60,MATCH(B17,Reaches!$B$7:$B$60,0)),"") | D17: 2750 | E17: 7000
A18: =IF(ISBLANK(B18),A17,IFERROR(INDEX(Reaches!$A$7:$A$60,MATCH(B18,Reaches!$B$7:$B$60,0)),-1)) -> 1 | C18: =IFERROR(INDEX(Reaches!$G$7:$G$60,MATCH(B18,Reaches!$B$7:$B$60,0)),"") | D18: 2953 | E18: 8000
A19: =IF(ISBLANK(B19),A18,IFERROR(INDEX(Reaches!$A$7:$A$60,MATCH(B19,Reaches!$B$7:$B$60,0)),-1)) -> 1 | C19: =IFERROR(INDEX(Reaches!$G$7:$G$60,MATCH(B19,Reaches!$B$7:$B$60,0)),"") | D19: 3160 | E19: 9000
... A27: =IF(ISBLANK(B27),A26,IFERROR(INDEX(Reaches!$A$7:$A$60,MATCH(B27,Reaches!$B$7:$B$60,0)),-1)) -> 1 | C27: =IFERROR(INDEX(Reaches!$G$7:$G$60,MATCH(B27,Reaches!$B$7:$B$60,0)),"") | D27: 281407 | E27: 3200000
A28: =IF(ISBLANK(B28),A27,IFERROR(INDEX(Reaches!$A$7:$A$60,MATCH(B28,Reaches!$B$7:$B$60,0)),-1)) -> 2 | B28: MFWillametteRV_R60 | C28: =IFERROR(INDEX(Reaches!$G$7:$G$60,MATCH(B28,Reaches!$B$7:$B$60,0)),"") -> 1 | D28: 0 | E28: 0
A29: =IF(ISBLANK(B29),A28,IFERROR(INDEX(Reaches!$A$7:$A$60,MATCH(B29,Reaches!$B$7:$B$60,0)),-1)) -> 2 | C29: =IFERROR(INDEX(Reaches!$G$7:$G$60,MATCH(B29,Reaches!$B$7:$B$60,0)),"") | D29: 192 | E29: 500
A30: =IF(ISBLANK(B30),A29,IFERROR(INDEX(Reaches!$A$7:$A$60,MATCH(B30,Reaches!$B$7:$B$60,0)),-1)) -> 2 | C30: =IFERROR(INDEX(Reaches!$G$7:$G$60,MATCH(B30,Reaches!$B$7:$B$60,0)),"") | D30: 197 | E30: 501
A31: =IF(ISBLANK(B31),A30,IFERROR(INDEX(Reaches!$A$7:$A$60,MATCH(B31,Reaches!$B$7:$B$60,0)),-1)) -> 2 | C31: =IFERROR(INDEX(Reaches!$G$7:$G$60,MATCH(B31,Reaches!$B$7:$B$60,0)),"") | D31: 247 | E31: 1000
A32: =IF(ISBLANK(B32),A31,IFERROR(INDEX(Reaches!$A$7:$A$60,MATCH(B32,Reaches!$B$7:$B$60,0)),-1)) -> 2 | C32: =IFERROR(INDEX(Reaches!$G$7:$G$60,MATCH(B32,Reaches!$B$7:$B$60,0)),"") | D32: 292 | E32: 1500
A33: =IF(ISBLANK(B33),A32,IFERROR(INDEX(Reaches!$A$7:$A$60,MATCH(B33,Reaches!$B$7:$B$60,0)),-1)) -> 2 | C33: =IFERROR(INDEX(Reaches!$G$7:$G$60,MATCH(B33,Reaches!$B$7:$B$60,0)),"") | D33: 335 | E33: 2000
A34: =IF(ISBLANK(B34),A33,IFERROR(INDEX(Reaches!$A$7:$A$60,MATCH(B34,Reaches!$B$7:$B$60,0)),-1)) -> 2 | C34: =IFERROR(INDEX(Reaches!$G$7:$G$60,MATCH(B34,Reaches!$B$7:$B$60,0)),"") | D34: 419 | E34: 3000
A35: =IF(ISBLANK(B35),A34,IFERROR(INDEX(Reaches!$A$7:$A$60,MATCH(B35,Reaches!$B$7:$B$60,0)),-1)) -> 2 | C35: =IFERROR(INDEX(Reaches!$G$7:$G$60,MATCH(B35,Reaches!$B$7:$B$60,0)),"") | D35: 501 | E35: 4000
A36: =IF(ISBLANK(B36),A35,IFERROR(INDEX(Reaches!$A$7:$A$60,MATCH(B36,Reaches!$B$7:$B$60,0)),-1)) -> 2 | C36: =IFERROR(INDEX(Reaches!$G$7:$G$60,MATCH(B36,Reaches!$B$7:$B$60,0)),"") | D36: 583 | E36: 5000
A37: =IF(ISBLANK(B37),A36,IFERROR(INDEX(Reaches!$A$7:$A$60,MATCH(B37,Reaches!$B$7:$B$60,0)),-1)) -> 2 | C37: =IFERROR(INDEX(Reaches!$G$7:$G$60,MATCH(B37,Reaches!$B$7:$B$60,0)),"") | D37: 663 | E37: 6000
A38: =IF(ISBLANK(B38),A37,IFERROR(INDEX(Reaches!$A$7:$A$60,MATCH(B38,Reaches!$B$7:$B$60,0)),-1)) -> 2 | C38: =IFERROR(INDEX(Reaches!$G$7:$G$60,MATCH(B38,Reaches!$B$7:$B$60,0)),"") | D38: 745 | E38: 7000
A39: =IF(ISBLANK(B39),A38,IFERROR(INDEX(Reaches!$A$7:$A$60,MATCH(B39,Reaches!$B$7:$B$60,0)),-1)) -> 2 | C39: =IFERROR(INDEX(Reaches!$G$7:$G$60,MATCH(B39,Reaches!$B$7:$B$60,0)),"") | D39: 823 | E39: 8000
A40: =IF(ISBLANK(B40),A39,IFERROR(INDEX(Reaches!$A$7:$A$60,MATCH(B40,Reaches!$B$7:$B$60,0)),-1)) -> 2 | C40: =IFERROR(INDEX(Reaches!$G$7:$G$60,MATCH(B40,Reaches!$B$7:$B$60,0)),"") | D40: 902 | E40: 9000
... A48: =IF(ISBLANK(B48),A47,IFERROR(INDEX(Reaches!$A$7:$A$60,MATCH(B48,Reaches!$B$7:$B$60,0)),-1)) -> 2 | C48: =IFERROR(INDEX(Reaches!$G$7:$G$60,MATCH(B48,Reaches!$B$7:$B$60,0)),"") | D48: 159425 | E48: 3100000
A49: =IF(ISBLANK(B49),A48,IFERROR(INDEX(Reaches!$A$7:$A$60,MATCH(B49,Reaches!$B$7:$B$60,0)),-1)) -> 3 | B49: MFWillametteRV_R55 | C49: =IFERROR(INDEX(Reaches!$G$7:$G$60,MATCH(B49,Reaches!$B$7:$B$60,0)),"") -> 2 | D49: 0 | E49: 0 | F49: New from Chris Nygaard
A50: =IF(ISBLANK(B50),A49,IFERROR(INDEX(Reaches!$A$7:$A$60,MATCH(B50,Reaches!$B$7:$B$60,0)),-1)) -> 3 | C50: =IFERROR(INDEX(Reaches!$G$7:$G$60,MATCH(B50,Reaches!$B$7:$B$60,0)),"") | D50: 669.15 | E50: 500
A51: =IF(ISBLANK(B51),A50,IFERROR(INDEX(Reaches!$A$7:$A$60,MATCH(B51,Reaches!$B$7:$B$60,0)),-1)) -> 3 | C51: =IFERROR(INDEX(Reaches!$G$7:$G$60,MATCH(B51,Reaches!$B$7:$B$60,0)),"") | D51: 1058.55 | E51: 1000
A52: =IF(ISBLANK(B52),A51,IFERROR(INDEX(Reaches!$A$7:$A$60,MATCH(B52,Reaches!$B$7:$B$60,0)),-1)) -> 3 | C52: =IFERROR(INDEX(Reaches!$G$7:$G$60,MATCH(B52,Reaches!$B$7:$B$60,0)),"") | D52: 1361.54 | E52: 1500
A53: =IF(ISBLANK(B53),A52,IFERROR(INDEX(Reaches!$A$7:$A$60,MATCH(B53,Reaches!$B$7:$B$60,0)),-1)) -> 3 | C53: =IFERROR(INDEX(Reaches!$G$7:$G$60,MATCH(B53,Reaches!$B$7:$B$60,0)),"") | D53: 1632.26 | E53: 2000
A54: =IF(ISBLANK(B54),A53,IFERROR(INDEX(Reaches!$A$7:$A$60,MATCH(B54,Reaches!$B$7:$B$60,0)),-1)) -> 3 | C54: =IFERROR(INDEX(Reaches!$G$7:$G$60,MATCH(B54,Reaches!$B$7:$B$60,0)),"") | D54: 2112.16 | E54: 3000
A55: =IF(ISBLANK(B55),A54,IFERROR(INDEX(Reaches!$A$7:$A$60,MATCH(B55,Reaches!$B$7:$B$60,0)),-1)) -> 3 | C55: =IFERROR(INDEX(Reaches!$G$7:$G$60,MATCH(B55,Reaches!$B$7:$B$60,0)),"") | D55: 2564.61 | E55: 4000
A56: =IF(ISBLANK(B56),A55,IFERROR(INDEX(Reaches!$A$7:$A$60,MATCH(B56,Reaches!$B$7:$B$60,0)),-1)) -> 3 | C56: =IFERROR(INDEX(Reaches!$G$7:$G$60,MATCH(B56,Reaches!$B$7:$B$60,0)),"") | D56: 2980.86 | E56: 5000
...
